<?xml version="1.0" encoding="utf-8"?>
<!-- This URDF was automatically created by SolidWorks to URDF Exporter! Originally created by Stephen Brawner (brawner@gmail.com)
     Commit Version: 1.6.0-4-g7f85cfe  Build Version: 1.6.7995.38578
     For more information, please see http://wiki.ros.org/sw_urdf_exporter -->
<robot
  name="Dual_S101_Assembly">
  <link
    name="dual_arm_base">
    <inertial>
      <origin
        xyz="-0.0178305299775216 -0.0312739666747981 0.495861472904819"
        rpy="0 0 0" />
      <mass
        value="0.113223328532494" />
      <inertia
        ixx="4.32536013472457E-05"
        ixy="4.80940408470063E-07"
        ixz="-3.84409745863671E-07"
        iyy="0.000100588548123803"
        iyz="-6.90395402582089E-06"
        izz="0.000117560067330291" />
    </inertial>
    <visual>
      <origin
        xyz="0 0 0"
        rpy="0 0 0" />
      <geometry>
        <mesh
          filename="meshes/dual_arm_base.STL" />
      </geometry>
      <material
        name="">
        <color
          rgba="0.752941176470588 0.752941176470588 0.752941176470588 1" />
      </material>
    </visual>
    <collision>
      <origin
        xyz="0 0 0"
        rpy="0 0 0" />
      <geometry>
        <mesh
          filename="meshes/dual_arm_base.STL" />
      </geometry>
    </collision>
  </link>
  <link
    name="left_base">
    <inertial>
      <origin
        xyz="0.0162346687723646 -3.83724601515506E-05 0.0312250752546322"
        rpy="0 0 0" />
      <mass
        value="0.19173383972435" />
      <inertia
        ixx="0.000152939124549041"
        ixy="-5.13155925834886E-07"
        ixz="2.1208078238967E-05"
        iyy="0.000140329549233141"
        iyz="-2.4332900270951E-09"
        izz="0.000177680306692991" />
    </inertial>
    <visual>
      <origin
        xyz="0 0 0"
        rpy="0 0 0" />
      <geometry>
        <mesh
          filename="meshes/left_base.STL" />
      </geometry>
      <material
        name="">
        <color
          rgba="0.964705882352941 0.964705882352941 0.952941176470588 1" />
      </material>
    </visual>
    <collision>
      <origin
        xyz="0 0 0"
        rpy="0 0 0" />
      <geometry>
        <mesh
          filename="meshes/left_base.STL" />
      </geometry>
    </collision>
  </link>
  <joint
    name="left_joint_0"
    type="fixed">
    <origin
      xyz="0.11603 -0.0146 0.0048"
      rpy="0 0 -1.5708" />
    <parent
      link="dual_arm_base" />
    <child
      link="left_base" />
    <axis
      xyz="0 0 0" />
  </joint>
  <link
    name="left_shoulder">
    <inertial>
      <origin
        xyz="-0.031142635636725 -0.000121917022185905 -0.0110181845545189"
        rpy="0 0 0" />
      <mass
        value="0.118341939887238" />
      <inertia
        ixx="5.86113763858292E-05"
        ixy="8.61016250704921E-08"
        ixz="-4.52834126978146E-06"
        iyy="5.99919497140707E-05"
        iyz="-4.41406769865219E-07"
        izz="3.2731977952912E-05" />
    </inertial>
    <visual>
      <origin
        xyz="0 0 0"
        rpy="0 0 0" />
      <geometry>
        <mesh
          filename="meshes/left_shoulder.STL" />
      </geometry>
      <material
        name="">
        <color
          rgba="0.964705882352941 0.964705882352941 0.952941176470588 1" />
      </material>
    </visual>
    <collision>
      <origin
        xyz="0 0 0"
        rpy="0 0 0" />
      <geometry>
        <mesh
          filename="meshes/left_shoulder.STL" />
      </geometry>
    </collision>
  </link>
  <joint
    name="left_joint_1"
    type="revolute">
    <origin
      xyz="0.0452 0 0.0648"
      rpy="3.1416 0 -3.1416" />
    <parent
      link="left_base" />
    <child
      link="left_shoulder" />
    <axis
      xyz="0 0 1" />
    <limit
      lower="-1.9199"
      upper="1.9199"
      effort="3.0"
      velocity="10" />
    <dynamics
      damping="0.1"
      friction="0.1" />
    <safety_controller
      soft_upper_limit="1.8326"
      soft_lower_limit="-1.8326"
      k_position="100"
      k_velocity="10" />
  </joint>
  <link
    name="left_upper_arm">
    <inertial>
      <origin
        xyz="-0.0728206340591942 -0.00327441510690678 0.0182861176478301"
        rpy="0 0 0" />
      <mass
        value="0.15363212902419" />
      <inertia
        ixx="6.05949137462722E-05"
        ixy="2.03942902703261E-06"
        ixz="-1.39579952363567E-06"
        iyy="0.000189440396477305"
        iyz="-1.38443815875347E-07"
        izz="0.000151916888224126" />
    </inertial>
    <visual>
      <origin
        xyz="0 0 0"
        rpy="0 0 0" />
      <geometry>
        <mesh
          filename="meshes/left_upper_arm.STL" />
      </geometry>
      <material
        name="">
        <color
          rgba="0.964705882352941 0.964705882352941 0.952941176470588 1" />
      </material>
    </visual>
    <collision>
      <origin
        xyz="0 0 0"
        rpy="0 0 0" />
      <geometry>
        <mesh
          filename="meshes/left_upper_arm.STL" />
      </geometry>
    </collision>
  </link>
  <joint
    name="left_joint_2"
    type="revolute">
    <origin
      xyz="-0.0306 -0.0183 -0.0542"
      rpy="-1.5708 -1.5708 0" />
    <parent
      link="left_shoulder" />
    <child
      link="left_upper_arm" />
    <axis
      xyz="0 0 1" />
    <limit
      lower="-1.7453"
      upper="1.7453"
      effort="3.0"
      velocity="10" />
    <dynamics
      damping="0.1"
      friction="0.1" />
    <safety_controller
      soft_upper_limit="1.6581"
      soft_lower_limit="-1.6581"
      k_position="100"
      k_velocity="10" />
  </joint>
  <link
    name="left_lower_arm">
    <inertial>
      <origin
        xyz="-0.0775719382382264 0.00151952534810351 0.0180810175073838"
        rpy="0 0 0" />
      <mass
        value="0.143060147475685" />
      <inertia
        ixx="4.97460992968506E-05"
        ixy="-1.66006625280883E-06"
        ixz="8.74081902598206E-07"
        iyy="0.000134184383760885"
        iyz="6.16843370177025E-08"
        izz="0.000101485796665944" />
    </inertial>
    <visual>
      <origin
        xyz="0 0 0"
        rpy="0 0 0" />
      <geometry>
        <mesh
          filename="meshes/left_lower_arm.STL" />
      </geometry>
      <material
        name="">
        <color
          rgba="0.964705882352941 0.964705882352941 0.952941176470588 1" />
      </material>
    </visual>
    <collision>
      <origin
        xyz="0 0 0"
        rpy="0 0 0" />
      <geometry>
        <mesh
          filename="meshes/left_lower_arm.STL" />
      </geometry>
    </collision>
  </link>
  <joint
    name="left_joint_3"
    type="revolute">
    <origin
      xyz="-0.11257 -0.028 0"
      rpy="0 0 1.5708" />
    <parent
      link="left_upper_arm" />
    <child
      link="left_lower_arm" />
    <axis
      xyz="0 0 1" />
    <limit
      lower="-1.7453"
      upper="1.5708"
      effort="3.0"
      velocity="10" />
    <dynamics
      damping="0.1"
      friction="0.1" />
    <safety_controller
      soft_upper_limit="1.4835"
      soft_lower_limit="-1.6581"
      k_position="100"
      k_velocity="10" />
  </joint>
  <link
    name="left_wrist">
    <inertial>
      <origin
        xyz="-0.000184791961547442 -0.0353221206101238 0.025761322149223"
        rpy="0 0 0" />
      <mass
        value="0.0679708516273379" />
      <inertia
        ixx="3.41516470839204E-05"
        ixy="-1.17324864266176E-07"
        ixz="2.22549206578718E-08"
        iyy="2.44773195608375E-05"
        iyz="1.70608957623072E-06"
        izz="1.91135045565851E-05" />
    </inertial>
    <visual>
      <origin
        xyz="0 0 0"
        rpy="0 0 0" />
      <geometry>
        <mesh
          filename="meshes/left_wrist.STL" />
      </geometry>
      <material
        name="">
        <color
          rgba="0.964705882352941 0.964705882352941 0.952941176470588 1" />
      </material>
    </visual>
    <collision>
      <origin
        xyz="0 0 0"
        rpy="0 0 0" />
      <geometry>
        <mesh
          filename="meshes/left_wrist.STL" />
      </geometry>
    </collision>
  </link>
  <joint
    name="left_joint_4"
    type="revolute">
    <origin
      xyz="-0.1349 0.0052 0.0001"
      rpy="0 0 -1.5708" />
    <parent
      link="left_lower_arm" />
    <child
      link="left_wrist" />
    <axis
      xyz="0 0 1" />
    <limit
      lower="-1.6581"
      upper="1.6581"
      effort="3.0"
      velocity="10" />
    <dynamics
      damping="0.1"
      friction="0.1" />
    <safety_controller
      soft_upper_limit="1.5708"
      soft_lower_limit="-1.5708"
      k_position="100"
      k_velocity="10" />
  </joint>
  <link
    name="left_gripper">
    <inertial>
      <origin
        xyz="-0.00574752721018881 0.000439341267677723 -0.0266680289023382"
        rpy="0 0 0" />
      <mass
        value="0.092841669574477" />
      <inertia
        ixx="4.186396427962E-05"
        ixy="-5.47746420935492E-07"
        ixz="-6.83555875832769E-06"
        iyy="4.93735843503565E-05"
        iyz="-1.12209425132196E-07"
        izz="2.99241051160195E-05" />
    </inertial>
    <visual>
      <origin
        xyz="0 0 0"
        rpy="0 0 0" />
      <geometry>
        <mesh
          filename="meshes/left_gripper.STL" />
      </geometry>
      <material
        name="">
        <color
          rgba="0.964705882352941 0.964705882352941 0.952941176470588 1" />
      </material>
    </visual>
    <collision>
      <origin
        xyz="0 0 0"
        rpy="0 0 0" />
      <geometry>
        <mesh
          filename="meshes/left_gripper.STL" />
      </geometry>
    </collision>
  </link>
  <joint
    name="left_joint_5"
    type="revolute">
    <origin
      xyz="0 -0.0611 0.017882"
      rpy="1.5708 0 3.1416" />
    <parent
      link="left_wrist" />
    <child
      link="left_gripper" />
    <axis
      xyz="0 0 1" />
    <limit
      lower="-2.7925"
      upper="2.7925"
      effort="3.0"
      velocity="10" />
    <dynamics
      damping="0.1"
      friction="0.1" />
    <safety_controller
      soft_upper_limit="2.7053"
      soft_lower_limit="-2.7053"
      k_position="100"
      k_velocity="10" />
  </joint>
  <link
    name="left_jaw">
    <inertial>
      <origin
        xyz="-0.0015747081403174 -0.0300218594135709 0.019275602442142"
        rpy="0 0 0" />
      <mass
        value="0.0206924694063983" />
      <inertia
        ixx="1.14040266296032E-05"
        ixy="-5.5140615838995E-07"
        ixz="-1.01818943800375E-08"
        iyy="3.25982231241225E-06"
        iyz="-1.8947308010859E-07"
        izz="9.11579055714954E-06" />
    </inertial>
    <visual>
      <origin
        xyz="0 0 0"
        rpy="0 0 0" />
      <geometry>
        <mesh
          filename="meshes/left_jaw.STL" />
      </geometry>
      <material
        name="">
        <color
          rgba="0.964705882352941 0.964705882352941 0.952941176470588 1" />
      </material>
    </visual>
    <collision>
      <origin
        xyz="0 0 0"
        rpy="0 0 0" />
      <geometry>
        <mesh
          filename="meshes/left_jaw.STL" />
      </geometry>
    </collision>
  </link>
  <joint
    name="left_joint_6"
    type="revolute">
    <origin
      xyz="0.0202 0.018918 -0.0234"
      rpy="1.5708 0 0" />
    <parent
      link="left_gripper" />
    <child
      link="left_jaw" />
    <axis
      xyz="0 0 1" />
    <limit
      lower="-0.1745"
      upper="1.7453"
      effort="3.0"
      velocity="10" />
    <dynamics
      damping="0.05"
      friction="0.05" />
    <safety_controller
      soft_upper_limit="1.6581"
      soft_lower_limit="0.0873"
      k_position="50"
      k_velocity="5" />
  </joint>
  <link
    name="right_base">
    <inertial>
      <origin
        xyz="0.0162346687724207 -3.8372460282432E-05 0.0312250752543982"
        rpy="0 0 0" />
      <mass
        value="0.191733839722778" />
      <inertia
        ixx="0.000152939124548659"
        ixy="-5.13155925943902E-07"
        ixz="2.12080782391042E-05"
        iyy="0.00014032954923335"
        iyz="-2.43328979067538E-09"
        izz="0.000177680306692724" />
    </inertial>
    <visual>
      <origin
        xyz="0 0 0"
        rpy="0 0 0" />
      <geometry>
        <mesh
          filename="meshes/right_base.STL" />
      </geometry>
      <material
        name="">
        <color
          rgba="0.964705882352941 0.964705882352941 0.952941176470588 1" />
      </material>
    </visual>
    <collision>
      <origin
        xyz="0 0 0"
        rpy="0 0 0" />
      <geometry>
        <mesh
          filename="meshes/right_base.STL" />
      </geometry>
    </collision>
  </link>
  <joint
    name="right_joint_0"
    type="fixed">
    <origin
      xyz="-0.11603 -0.0146 0.0048"
      rpy="0 0 -1.5708" />
    <parent
      link="dual_arm_base" />
    <child
      link="right_base" />
    <axis
      xyz="0 0 0" />
  </joint>
  <link
    name="right_shoulder">
    <inertial>
      <origin
        xyz="-0.0311426356538473 -0.00012191698790015 -0.0110181845504216"
        rpy="0 0 0" />
      <mass
        value="0.118341939633333" />
      <inertia
        ixx="5.8611376294277E-05"
        ixy="8.61015905160519E-08"
        ixz="-4.52834124410574E-06"
        iyy="5.99919496601621E-05"
        iyz="-4.41406815526837E-07"
        izz="3.27319778730881E-05" />
    </inertial>
    <visual>
      <origin
        xyz="0 0 0"
        rpy="0 0 0" />
      <geometry>
        <mesh
          filename="meshes/right_shoulder.STL" />
      </geometry>
      <material
        name="">
        <color
          rgba="0.964705882352941 0.964705882352941 0.952941176470588 1" />
      </material>
    </visual>
    <collision>
      <origin
        xyz="0 0 0"
        rpy="0 0 0" />
      <geometry>
        <mesh
          filename="meshes/right_shoulder.STL" />
      </geometry>
    </collision>
  </link>
  <joint
    name="right_joint_1"
    type="revolute">
    <origin
      xyz="0.0452 0 0.0648"
      rpy="3.1416 0 -3.1416" />
    <parent
      link="right_base" />
    <child
      link="right_shoulder" />
    <axis
      xyz="0 0 1" />
    <limit
      lower="-1.9199"
      upper="1.9199"
      effort="3.0"
      velocity="10" />
    <dynamics
      damping="0.1"
      friction="0.1" />
    <safety_controller
      soft_upper_limit="1.8326"
      soft_lower_limit="-1.8326"
      k_position="100"
      k_velocity="10" />
  </joint>
  <link
    name="right_upper_arm">
    <inertial>
      <origin
        xyz="-0.0728206340591972 -0.00327441510690678 0.250350263689704"
        rpy="0 0 0" />
      <mass
        value="0.15363212902419" />
      <inertia
        ixx="6.05949137462722E-05"
        ixy="2.03942902703258E-06"
        ixz="-1.39579952363567E-06"
        iyy="0.000189440396477305"
        iyz="-1.38443815875406E-07"
        izz="0.000151916888224126" />
    </inertial>
    <visual>
      <origin
        xyz="0 0 0"
        rpy="0 0 0" />
      <geometry>
        <mesh
          filename="meshes/right_upper_arm.STL" />
      </geometry>
      <material
        name="">
        <color
          rgba="0.964705882352941 0.964705882352941 0.952941176470588 1" />
      </material>
    </visual>
    <collision>
      <origin
        xyz="0 0 0"
        rpy="0 0 0" />
      <geometry>
        <mesh
          filename="meshes/right_upper_arm.STL" />
      </geometry>
    </collision>
  </link>
  <joint
    name="right_joint_2"
    type="revolute">
    <origin
      xyz="-0.0306 -0.0183 -0.0542"
      rpy="-1.5708 -1.5708 0" />
    <parent
      link="right_shoulder" />
    <child
      link="right_upper_arm" />
    <axis
      xyz="0 0 1" />
    <limit
      lower="-1.7453"
      upper="1.7453"
      effort="3.0"
      velocity="10" />
    <dynamics
      damping="0.1"
      friction="0.1" />
    <safety_controller
      soft_upper_limit="1.6581"
      soft_lower_limit="-1.6581"
      k_position="100"
      k_velocity="10" />
  </joint>
  <link
    name="right_lower_arm">
    <inertial>
      <origin
        xyz="-0.0775719380306736 0.00151952533594926 0.0180810175945359"
        rpy="0 0 0" />
      <mass
        value="0.143060148064918" />
      <inertia
        ixx="4.97460996394073E-05"
        ixy="-1.66006621154095E-06"
        ixz="8.74081440084484E-07"
        iyy="0.000134184384767867"
        iyz="6.16843747496445E-08"
        izz="0.000101485797346287" />
    </inertial>
    <visual>
      <origin
        xyz="0 0 0"
        rpy="0 0 0" />
      <geometry>
        <mesh
          filename="meshes/right_lower_arm.STL" />
      </geometry>
      <material
        name="">
        <color
          rgba="0.964705882352941 0.964705882352941 0.952941176470588 1" />
      </material>
    </visual>
    <collision>
      <origin
        xyz="0 0 0"
        rpy="0 0 0" />
      <geometry>
        <mesh
          filename="meshes/right_lower_arm.STL" />
      </geometry>
    </collision>
  </link>
  <joint
    name="right_joint_3"
    type="revolute">
    <origin
      xyz="-0.11257 -0.028 0"
      rpy="0 0 1.5708" />
    <parent
      link="right_upper_arm" />
    <child
      link="right_lower_arm" />
    <axis
      xyz="0 0 1" />
    <limit
      lower="-1.7453"
      upper="1.5708"
      effort="3.0"
      velocity="10" />
    <dynamics
      damping="0.1"
      friction="0.1" />
    <safety_controller
      soft_upper_limit="1.4835"
      soft_lower_limit="-1.6581"
      k_position="100"
      k_velocity="10" />
  </joint>
  <link
    name="right_wrist">
    <inertial>
      <origin
        xyz="-0.00018479196122978 -0.0353221206091248 0.0257613221479055"
        rpy="0 0 0" />
      <mass
        value="0.0679708516331742" />
      <inertia
        ixx="3.41516470842545E-05"
        ixy="-1.1732486436127E-07"
        ixz="2.22549209410521E-08"
        iyy="2.4477319561352E-05"
        iyz="1.70608957642031E-06"
        izz="1.91135045565082E-05" />
    </inertial>
    <visual>
      <origin
        xyz="0 0 0"
        rpy="0 0 0" />
      <geometry>
        <mesh
          filename="meshes/right_wrist.STL" />
      </geometry>
      <material
        name="">
        <color
          rgba="0.964705882352941 0.964705882352941 0.952941176470588 1" />
      </material>
    </visual>
    <collision>
      <origin
        xyz="0 0 0"
        rpy="0 0 0" />
      <geometry>
        <mesh
          filename="meshes/right_wrist.STL" />
      </geometry>
    </collision>
  </link>
  <joint
    name="right_joint_4"
    type="revolute">
    <origin
      xyz="-0.1349 0.0052 0.0001"
      rpy="0 0 -1.5708" />
    <parent
      link="right_lower_arm" />
    <child
      link="right_wrist" />
    <axis
      xyz="0 0 1" />
    <limit
      lower="-1.6581"
      upper="1.6581"
      effort="3.0"
      velocity="10" />
    <dynamics
      damping="0.1"
      friction="0.1" />
    <safety_controller
      soft_upper_limit="1.5708"
      soft_lower_limit="-1.5708"
      k_position="100"
      k_velocity="10" />
  </joint>
  <link
    name="right_gripper">
    <inertial>
      <origin
        xyz="-0.00574752763582106 0.000439341024686582 -0.0266680290882676"
        rpy="0 0 0" />
      <mass
        value="0.092841671279361" />
      <inertia
        ixx="4.18639646796772E-05"
        ixy="-5.47746817354447E-07"
        ixz="-6.83555897415518E-06"
        iyy="4.93735846283438E-05"
        iyz="-1.12209606296432E-07"
        izz="2.99241055713867E-05" />
    </inertial>
    <visual>
      <origin
        xyz="0 0 0"
        rpy="0 0 0" />
      <geometry>
        <mesh
          filename="meshes/right_gripper.STL" />
      </geometry>
      <material
        name="">
        <color
          rgba="0.964705882352941 0.964705882352941 0.952941176470588 1" />
      </material>
    </visual>
    <collision>
      <origin
        xyz="0 0 0"
        rpy="0 0 0" />
      <geometry>
        <mesh
          filename="meshes/right_gripper.STL" />
      </geometry>
    </collision>
  </link>
  <joint
    name="right_joint_5"
    type="revolute">
    <origin
      xyz="0 -0.0611 0.017882"
      rpy="1.5708 0 -3.1416" />
    <parent
      link="right_wrist" />
    <child
      link="right_gripper" />
    <axis
      xyz="0 0 1" />
    <limit
      lower="-2.7925"
      upper="2.7925"
      effort="3.0"
      velocity="10" />
    <dynamics
      damping="0.1"
      friction="0.1" />
    <safety_controller
      soft_upper_limit="2.7053"
      soft_lower_limit="-2.7053"
      k_position="100"
      k_velocity="10" />
  </joint>
  <link
    name="right_jaw">
    <inertial>
      <origin
        xyz="-0.00157470813994792 -0.030021859344342 0.0192756025489046"
        rpy="0 0 0" />
      <mass
        value="0.020692469407428" />
      <inertia
        ixx="1.14040266298022E-05"
        ixy="-5.51406158479579E-07"
        ixz="-1.01818923166254E-08"
        iyy="3.25982231126522E-06"
        iyz="-1.89473059087859E-07"
        izz="9.11579055861443E-06" />
    </inertial>
    <visual>
      <origin
        xyz="0 0 0"
        rpy="0 0 0" />
      <geometry>
        <mesh
          filename="meshes/right_jaw.STL" />
      </geometry>
      <material
        name="">
        <color
          rgba="0.964705882352941 0.964705882352941 0.952941176470588 1" />
      </material>
    </visual>
    <collision>
      <origin
        xyz="0 0 0"
        rpy="0 0 0" />
      <geometry>
        <mesh
          filename="meshes/right_jaw.STL" />
      </geometry>
    </collision>
  </link>
  <joint
    name="right_joint_6"
    type="revolute">
    <origin
      xyz="0.0202 0.018918 -0.0234"
      rpy="1.5708 0 0" />
    <parent
      link="right_gripper" />
    <child
      link="right_jaw" />
    <axis
      xyz="0 0 1" />
    <limit
      lower="-0.1745"
      upper="1.7453"
      effort="3.0"
      velocity="10" />
    <dynamics
      damping="0.05"
      friction="0.05" />
    <safety_controller
      soft_upper_limit="1.6581"
      soft_lower_limit="0.0873"
      k_position="50"
      k_velocity="5" />
  </joint>
</robot>
